<robot name="grq20_v1d6_airy">
  <link name="base_link">
    <inertial>
      <origin xyz="0.0094498 -0.0090544 0.0024967" rpy="0 0 0" />
      <mass value="19.9426357" />
      <inertia ixx="0.12497" iyy="0.576588" izz="0.6287693" ixy="0.0004594" ixz="-0.0137517" iyz="-0.0004353"/>
    </inertial>
    <visual>
      <origin xyz="0 0 0" rpy="0 0 0" />
      <geometry>
        <mesh filename="package://robot_visualization/assets/grq20_v1d6_airy/meshes/meshes_simplify/TRUCK.STL" scale="1 1 1"/>
      </geometry>
      <material name="">
        <color rgba="0.8 0.4 0 1" />
      </material>
    </visual>
    <collision>
      <origin xyz="0 0 -0.0145" rpy="0 0 0"/>
      <geometry>
        <box size="0.43 0.274 0.185" />
      </geometry>
    </collision>
    <collision>
      <origin xyz="0.3145 0 -0.003" rpy="0 0 0"/>
      <geometry>
        <box size="0.199 0.150 0.162" />
      </geometry>
    </collision>
    <collision>
      <origin xyz="0.3138 0 0.1195" rpy="0 0 0"/>
      <geometry>
        <box size="0.088 0.088 0.083" />
      </geometry>
    </collision>
    <collision>
      <origin xyz="-0.312 0 0" rpy="0 0 0"/>
      <geometry>
        <box size="0.194 0.12 0.148" />
      </geometry>
    </collision>
    <!-- template_collision_placeholder -->
  </link>

  <link name="airy_front">
    <visual>
      <origin xyz="0 0 0" rpy="0 0 0" />
      <geometry>
        <sphere radius="0.02" />
      </geometry>
    </visual>
  </link>

  <joint name="airy_front_joint" type="fixed">
    <origin xyz="0.3792 0.0 0.0" rpy="0 1.5707963 0" />
    <parent link="base_link" />
    <child link="airy_front" />
  </joint>

  <link name="airy_back">
    <visual>
      <origin xyz="0 0 0" rpy="0 0 0" />
      <geometry>
        <sphere radius="0.02" />
      </geometry>
    </visual>
  </link>

  <joint name="airy_back_joint" type="fixed">
    <origin xyz="-0.3947 0.0 0.0" rpy="0 1.5707963 3.1415926" />
    <parent link="base_link" />
    <child link="airy_back" />
  </joint>

  <link name="FL_hip">
    <inertial>
      <origin xyz="-0.0034539 0.0001471 -0.0009605" rpy="0 0 0" />
      <mass value="1.6459372" />
      <inertia ixx="0.0004144" iyy="0.000796" izz="0.0005767" ixy="1e-05" ixz="1.5e-06" iyz="-1.4e-06"/>
    </inertial>
    <visual>
      <origin xyz="0 0 0" rpy="0 0 0" />
      <geometry>
        <mesh filename="package://robot_visualization/assets/grq20_v1d6_airy/meshes/meshes_simplify/FL_HIP.STL" scale="1 1 1"/>
      </geometry>
      <material name="">
        <color rgba="1 0.4 0.4 1" />
      </material>
    </visual>
    <!-- <collision>
      <origin xyz="0 0 0" rpy="0 0 0"/>
      <geometry>
        <mesh filename="package://robot_visualization/assets/grq20_v1d6_airy/meshes/meshes_simplify/FL_HIP.STL" scale="1 1 1"/>
      </geometry>
    </collision> -->
    <!-- template_collision_placeholder -->
  </link>

  <joint name="FL_hip_joint" type="revolute">
    <origin xyz="0.279 0.067 0" rpy="0 0 0" />
    <parent link="base_link" />
    <child link="FL_hip" />
    <axis xyz="1 0 0" />
    <limit lower="-0.78539815" upper="0.78539815" effort="120" velocity="12.0" />
  </joint>

  <link name="FL_thigh">
    <inertial>
      <origin xyz="-0.0028001 -0.0368096 -0.0239021" rpy="0 0 0" />
      <mass value="2.2115554" />
      <inertia ixx="0.012133" iyy="0.0117725" izz="0.0019164" ixy="0.0002099" ixz="-0.000542" iyz="0.0020399"/>
    </inertial>
    <visual>
      <origin xyz="0 0 0" rpy="0 0 0" />
      <geometry>
        <mesh filename="package://robot_visualization/assets/grq20_v1d6_airy/meshes/meshes_simplify/FL_THIGH.STL" scale="1 1 1"/>
      </geometry>
      <material name="">
        <color rgba="1 1 0.4 1" />
      </material>
    </visual>
    <collision>
      <origin xyz="-0.025 0 -0.15" rpy="0 0 0"/>
      <geometry>
        <box size="0.05 0.02 0.18" />
      </geometry>
    </collision>
    <collision>
      <origin xyz="0 -0.065 0" rpy="1.57 1.57 0"/>
      <geometry>
        <cylinder radius="0.06" length="0.14" />
      </geometry>
    </collision>
    <!-- template_collision_placeholder -->
  </link>

  <joint name="FL_thigh_joint" type="revolute">
    <origin xyz="0 0.1103 0" rpy="0 0 0" />
    <parent link="FL_hip" />
    <child link="FL_thigh" />
    <axis xyz="0 1 0" />
    <limit lower="-1.762783" upper="3.647738" effort="120" velocity="12.0" />
  </joint>

  <link name="FL_calf">
    <inertial>
      <origin xyz="0.006276 6e-05 -0.1458107" rpy="0 0 0" />
      <mass value="0.3248308" />
      <inertia ixx="0.0041942" iyy="0.0042423" izz="9.93e-05" ixy="0" ixz="-3e-07" iyz="0"/>
    </inertial>
    <visual>
      <origin xyz="0 0 0" rpy="0 0 0" />
      <geometry>
        <mesh filename="package://robot_visualization/assets/grq20_v1d6_airy/meshes/meshes_simplify/FL_CALF.STL" scale="1 1 1"/>
      </geometry>
      <material name="">
        <color rgba="0.4 1 0.4 1" />
      </material>
    </visual>
    <collision>
      <origin xyz="0.015 0.0 -0.235" rpy="0 0.5 0"/>
      <geometry>
        <box size="0.04 0.02 0.05" />
      </geometry>
    </collision>
    <collision>
      <origin xyz="0.0085 0.0 -0.092" rpy="0 -0.15 0"/>
      <geometry>
        <box size="0.032 0.02 0.27" />
      </geometry>
    </collision>
    <!-- template_collision_placeholder -->
  </link>

  <joint name="FL_calf_joint" type="revolute">
    <origin xyz="0 0 -0.26" rpy="0 0 0" />
    <parent link="FL_thigh" />
    <child link="FL_calf" />
    <axis xyz="0 1 0" />
    <limit lower="-2.740167" upper="-0.383972" effort="120" velocity="12.0" />
  </joint>

  <link name="FL_foot">
    <inertial>
      <origin xyz="0 0 0" rpy="0 0 0" />
      <mass value="0.000204873572147578" />
      <inertia ixx="1.09600066619755e-09" iyy="1.09600066619755e-09" izz="1.09600066619755e-09" ixy="0" ixz="0" iyz="0"/>
    </inertial>
    <visual>
      <origin xyz="0 0 0" rpy="0 0 0" />
      <geometry>
        <sphere radius="0.026" />
      </geometry>
      <material name="">
        <color rgba="0 0.5 1 1" />
      </material>
    </visual>
    <collision>
      <origin xyz="0 0 0" rpy="0 0 0"/>
      <geometry>
        <sphere radius="0.026" />
      </geometry>
    </collision>
    <!-- template_collision_placeholder -->
  </link>

  <joint name="FL_foot_joint" type="fixed">
    <origin xyz="0 0 -0.26" rpy="0 0 0" />
    <parent link="FL_calf" />
    <child link="FL_foot" />
    <axis xyz="0 1 0" />
    <limit lower="0" upper="0" effort="0" velocity="0" />
  </joint>

  <link name="RL_hip">
    <inertial>
      <origin xyz="-0.0034539 0.0001471 -0.0009605" rpy="0 0 0" />
      <mass value="1.6459372" />
      <inertia ixx="0.0004144" iyy="0.000796" izz="0.0005767" ixy="-1e-05" ixz="-1.5e-06" iyz="-1.4e-06"/>
    </inertial>
    <visual>
      <origin xyz="0 0 0" rpy="0 0 0" />
      <geometry>
        <mesh filename="package://robot_visualization/assets/grq20_v1d6_airy/meshes/meshes_simplify/RL_HIP.STL" scale="1 1 1"/>
      </geometry>
      <material name="">
        <color rgba="0.8 1.0 0.8 1" />
      </material>
    </visual>
    <!-- <collision>
      <origin xyz="0 0 0" rpy="0 0 0"/>
      <geometry>
        <mesh filename="package://robot_visualization/assets/grq20_v1d6_airy/meshes/meshes_simplify/RL_HIP.STL" scale="1 1 1"/>
      </geometry>
    </collision> -->
    <!-- template_collision_placeholder -->
  </link>

  <joint name="RL_hip_joint" type="revolute">
    <origin xyz="-0.279 0.067 0" rpy="0 0 0" />
    <parent link="base_link" />
    <child link="RL_hip" />
    <axis xyz="1 0 0" />
    <limit lower="-0.78539815" upper="0.78539815" effort="120" velocity="12.0" />
  </joint>

  <link name="RL_thigh">
    <inertial>
      <origin xyz="-0.0028001 -0.0368096 -0.0239021" rpy="0 0 0" />
      <mass value="2.2115554" />
      <inertia ixx="0.012133" iyy="0.0117725" izz="0.0019164" ixy="0.0002099" ixz="-0.000542" iyz="0.0020399"/>
    </inertial>
    <visual>
      <origin xyz="0 0 0" rpy="0 0 0" />
      <geometry>
        <mesh filename="package://robot_visualization/assets/grq20_v1d6_airy/meshes/meshes_simplify/FL_THIGH.STL" scale="1 1 1"/>
      </geometry>
      <material name="">
        <color rgba="1 0.5 1 1" />
      </material>
    </visual>
    <collision>
      <origin xyz="-0.025 0 -0.15" rpy="0 0 0"/>
      <geometry>
        <box size="0.05 0.02 0.18" />
      </geometry>
    </collision>
    <collision>
      <origin xyz="0 -0.065 0" rpy="1.57 1.57 0"/>
      <geometry>
        <cylinder radius="0.06" length="0.14" />
      </geometry>
    </collision>
    <!-- template_collision_placeholder -->
  </link>

  <joint name="RL_thigh_joint" type="revolute">
    <origin xyz="0 0.1103 0" rpy="0 0 0" />
    <parent link="RL_hip" />
    <child link="RL_thigh" />
    <axis xyz="0 1 0" />
    <limit lower="-1.762783" upper="3.647738" effort="120" velocity="12.0" />
  </joint>

  <link name="RL_calf">
    <inertial>
      <origin xyz="0.006276 6e-05 -0.1458107" rpy="0 0 0" />
      <mass value="0.3248308" />
      <inertia ixx="0.0041942" iyy="0.0042423" izz="9.93e-05" ixy="0" ixz="-3e-07" iyz="0"/>
    </inertial>
    <visual>
      <origin xyz="0 0 0" rpy="0 0 0" />
      <geometry>
        <mesh filename="package://robot_visualization/assets/grq20_v1d6_airy/meshes/meshes_simplify/FL_CALF.STL" scale="1 1 1"/>
      </geometry>
      <material name="">
        <color rgba="1 0.4 0.4 1" />
      </material>
    </visual>
    <collision>
      <origin xyz="0.015 0.0 -0.235" rpy="0 0.5 0"/>
      <geometry>
        <box size="0.04 0.02 0.05" />
      </geometry>
    </collision>
    <collision>
      <origin xyz="0.0085 0.0 -0.092" rpy="0 -0.15 0"/>
      <geometry>
        <box size="0.032 0.02 0.27" />
      </geometry>
    </collision>
    <!-- template_collision_placeholder -->
  </link>

  <joint name="RL_calf_joint" type="revolute">
    <origin xyz="0 0 -0.26" rpy="0 0 0" />
    <parent link="RL_thigh" />
    <child link="RL_calf" />
    <axis xyz="0 1 0" />
    <limit lower="-2.740167" upper="-0.383972" effort="120" velocity="12.0" />
  </joint>

  <link name="RL_foot">
    <inertial>
      <origin xyz="0 0 0" rpy="0 0 0" />
      <mass value="0.000204873572147578" />
      <inertia ixx="1.09600066619755e-09" iyy="1.09600066619755e-09" izz="1.09600066619755e-09" ixy="0" ixz="0" iyz="0"/>
    </inertial>
    <visual>
      <origin xyz="0 0 0" rpy="0 0 0" />
      <geometry>
        <sphere radius="0.026" />
      </geometry>
      <material name="">
        <color rgba="1 1 0.4 1" />
      </material>
    </visual>
    <collision>
      <origin xyz="0 0 0" rpy="0 0 0"/>
      <geometry>
        <sphere radius="0.026" />
      </geometry>
    </collision>
    <!-- template_collision_placeholder -->
  </link>

  <joint name="RL_foot_joint" type="fixed">
    <origin xyz="0 0 -0.26" rpy="0 0 0" />
    <parent link="RL_calf" />
    <child link="RL_foot" />
    <axis xyz="0 1 0" />
    <limit lower="0" upper="0" effort="0" velocity="0" />
  </joint>

  <link name="FR_hip">
    <inertial>
      <origin xyz="-0.0034539 -0.0001471 -0.0009605" rpy="0 0 0" />
      <mass value="1.6459372" />
      <inertia ixx="0.0004144" iyy="0.000796" izz="0.0005767" ixy="-1e-05" ixz="1.5e-06" iyz="1.4e-06"/>
    </inertial>
    <visual>
      <origin xyz="0 0 0" rpy="0 0 0" />
      <geometry>
        <mesh filename="package://robot_visualization/assets/grq20_v1d6_airy/meshes/meshes_simplify/FL_HIP.STL" scale="1.0 -1.0 1.0"/>
      </geometry>
      <material name="">
        <color rgba="1 0.4 0.4 1" />
      </material>
    </visual>
    <!-- <collision>
      <origin xyz="0 0 0" rpy="0 0 0"/>
      <geometry>
        <mesh filename="package://robot_visualization/assets/grq20_v1d6_airy/meshes/meshes_simplify/FL_HIP.STL" scale="1.0 -1.0 1.0"/>
      </geometry>
    </collision> -->
    <!-- template_collision_placeholder -->
  </link>

  <joint name="FR_hip_joint" type="revolute">
    <origin xyz="0.279 -0.067 0.0" rpy="-0.0 0.0 -0.0" />
    <parent link="base_link" />
    <child link="FR_hip" />
    <axis xyz="1 0 0" />
    <limit lower="-0.78539815" upper="0.78539815" effort="120" velocity="12.0" />
  </joint>

  <link name="FR_thigh">
    <inertial>
      <origin xyz="-0.0028001 0.0368096 -0.0239021" rpy="0 0 0" />
      <mass value="2.2115554" />
      <inertia ixx="0.012133" iyy="0.0117725" izz="0.0019164" ixy="-0.0002099" ixz="-0.000542" iyz="-0.0020399"/>
    </inertial>
    <visual>
      <origin xyz="0 0 0" rpy="0 0 0" />
      <geometry>
        <mesh filename="package://robot_visualization/assets/grq20_v1d6_airy/meshes/meshes_simplify/FL_THIGH.STL" scale="1.0 -1.0 1.0"/>
      </geometry>
      <material name="">
        <color rgba="1 1 0.4 1" />
      </material>
    </visual>
    <collision>
      <origin xyz="-0.025 0 -0.15" rpy="0 0 0"/>
      <geometry>
        <box size="0.05 0.02 0.18" />
      </geometry>
    </collision>
    <collision>
      <origin xyz="0 0.065 0" rpy="1.57 1.57 0"/>
      <geometry>
        <cylinder radius="0.06" length="0.14" />
      </geometry>
    </collision>
    <!-- template_collision_placeholder -->
  </link>

  <joint name="FR_thigh_joint" type="revolute">
    <origin xyz="0.0 -0.1103 0.0" rpy="-0.0 0.0 -0.0" />
    <parent link="FR_hip" />
    <child link="FR_thigh" />
    <axis xyz="0 1 0" />
    <limit lower="-1.762783" upper="3.647738" effort="120" velocity="12.0" />
  </joint>

  <link name="FR_calf">
    <inertial>
      <origin xyz="0.006276 -6e-05 -0.1458107" rpy="0 0 0" />
      <mass value="0.3248308" />
      <inertia ixx="0.0041942" iyy="0.0042423" izz="9.93e-05" ixy="-0.0" ixz="-3e-07" iyz="-0.0"/>
    </inertial>
    <visual>
      <origin xyz="0 0 0" rpy="0 0 0" />
      <geometry>
        <mesh filename="package://robot_visualization/assets/grq20_v1d6_airy/meshes/meshes_simplify/FL_CALF.STL" scale="1.0 -1.0 1.0"/>
      </geometry>
      <material name="">
        <color rgba="0.4 1 0.4 1" />
      </material>
    </visual>
    <collision>
      <origin xyz="0.015 0.0 -0.235" rpy="0 0.5 0"/>
      <geometry>
        <box size="0.04 0.02 0.05" />
      </geometry>
    </collision>
    <collision>
      <origin xyz="0.0085 0.0 -0.092" rpy="0 -0.15 0"/>
      <geometry>
        <box size="0.032 0.02 0.27" />
      </geometry>
    </collision>
    <!-- template_collision_placeholder -->
  </link>

  <joint name="FR_calf_joint" type="revolute">
    <origin xyz="0.0 -0.0 -0.26" rpy="-0.0 0.0 -0.0" />
    <parent link="FR_thigh" />
    <child link="FR_calf" />
    <axis xyz="0 1 0" />
    <limit lower="-2.740167" upper="-0.383972" effort="120" velocity="12.0" />
  </joint>

  <link name="FR_foot">
    <inertial>
      <origin xyz="0.0 -0.0 0.0" rpy="0 0 0" />
      <mass value="0.000204873572147578" />
      <inertia ixx="1.09600066619755e-09" iyy="1.09600066619755e-09" izz="1.09600066619755e-09" ixy="-0.0" ixz="0.0" iyz="-0.0"/>
    </inertial>
    <visual>
      <origin xyz="0 0 0" rpy="0 0 0" />
      <geometry>
        <sphere radius="0.026" />
      </geometry>
      <material name="">
        <color rgba="0 0.5 1 1" />
      </material>
    </visual>
    <collision>
      <origin xyz="0 0 0" rpy="0 0 0"/>
      <geometry>
        <sphere radius="0.026" />
      </geometry>
    </collision>
    <!-- template_collision_placeholder -->
  </link>

  <joint name="FR_foot_joint" type="fixed">
    <origin xyz="0.0 -0.0 -0.26" rpy="-0.0 0.0 -0.0" />
    <parent link="FR_calf" />
    <child link="FR_foot" />
    <axis xyz="0 1 0" />
    <limit lower="0" upper="0" effort="0" velocity="0" />
  </joint>

  <link name="RR_hip">
    <inertial>
      <origin xyz="-0.0034539 -0.0001471 -0.0009605" rpy="0 0 0" />
      <mass value="1.6459372" />
      <inertia ixx="0.0004144" iyy="0.000796" izz="0.0005767" ixy="1e-05" ixz="-1.5e-06" iyz="1.4e-06"/>
    </inertial>
    <visual>
      <origin xyz="0 0 0" rpy="0 0 0" />
      <geometry>
        <mesh filename="package://robot_visualization/assets/grq20_v1d6_airy/meshes/meshes_simplify/RL_HIP.STL" scale="1.0 -1.0 1.0"/>
      </geometry>
      <material name="">
        <color rgba="0.8 1.0 0.8 1" />
      </material>
    </visual>
    <!-- <collision>
      <origin xyz="0 0 0" rpy="0 0 0"/>
      <geometry>
        <mesh filename="package://robot_visualization/assets/grq20_v1d6_airy/meshes/meshes_simplify/RL_HIP.STL" scale="1.0 -1.0 1.0"/>
      </geometry>
    </collision> -->
    <!-- template_collision_placeholder -->
  </link>

  <joint name="RR_hip_joint" type="revolute">
    <origin xyz="-0.279 -0.067 0.0" rpy="-0.0 0.0 -0.0" />
    <parent link="base_link" />
    <child link="RR_hip" />
    <axis xyz="1 0 0" />
    <limit lower="-0.78539815" upper="0.78539815" effort="120" velocity="12.0" />
  </joint>

  <link name="RR_thigh">
    <inertial>
      <origin xyz="-0.0028001 0.0368096 -0.0239021" rpy="0 0 0" />
      <mass value="2.2115554" />
      <inertia ixx="0.012133" iyy="0.0117725" izz="0.0019164" ixy="-0.0002099" ixz="-0.000542" iyz="-0.0020399"/>
    </inertial>
    <visual>
      <origin xyz="0 0 0" rpy="0 0 0" />
      <geometry>
        <mesh filename="package://robot_visualization/assets/grq20_v1d6_airy/meshes/meshes_simplify/FL_THIGH.STL" scale="1.0 -1.0 1.0"/>
      </geometry>
      <material name="">
        <color rgba="1 0.5 1 1" />
      </material>
    </visual>
    <collision>
      <origin xyz="-0.025 0 -0.15" rpy="0 0 0"/>
      <geometry>
        <box size="0.05 0.02 0.18" />
      </geometry>
    </collision>
    <collision>
      <origin xyz="0 0.065 0" rpy="1.57 1.57 0"/>
      <geometry>
        <cylinder radius="0.06" length="0.14" />
      </geometry>
    </collision>
    <!-- template_collision_placeholder -->
  </link>

  <joint name="RR_thigh_joint" type="revolute">
    <origin xyz="0.0 -0.1103 0.0" rpy="-0.0 0.0 -0.0" />
    <parent link="RR_hip" />
    <child link="RR_thigh" />
    <axis xyz="0 1 0" />
    <limit lower="-1.762783" upper="3.647738" effort="120" velocity="12.0" />
  </joint>

  <link name="RR_calf">
    <inertial>
      <origin xyz="0.006276 -6e-05 -0.1458107" rpy="0 0 0" />
      <mass value="0.3248308" />
      <inertia ixx="0.0041942" iyy="0.0042423" izz="9.93e-05" ixy="-0.0" ixz="-3e-07" iyz="-0.0"/>
    </inertial>
    <visual>
      <origin xyz="0 0 0" rpy="0 0 0" />
      <geometry>
        <mesh filename="package://robot_visualization/assets/grq20_v1d6_airy/meshes/meshes_simplify/FL_CALF.STL" scale="1.0 -1.0 1.0"/>
      </geometry>
      <material name="">
        <color rgba="1 0.4 0.4 1" />
      </material>
    </visual>
    <collision>
      <origin xyz="0.015 0.0 -0.235" rpy="0 0.5 0"/>
      <geometry>
        <box size="0.04 0.02 0.05" />
      </geometry>
    </collision>
    <collision>
      <origin xyz="0.0085 0.0 -0.092" rpy="0 -0.15 0"/>
      <geometry>
        <box size="0.032 0.02 0.27" />
      </geometry>
    </collision>
    <!-- template_collision_placeholder -->
  </link>

  <joint name="RR_calf_joint" type="revolute">
    <origin xyz="0.0 -0.0 -0.26" rpy="-0.0 0.0 -0.0" />
    <parent link="RR_thigh" />
    <child link="RR_calf" />
    <axis xyz="0 1 0" />
    <limit lower="-2.740167" upper="-0.383972" effort="120" velocity="12.0" />
  </joint>

  <link name="RR_foot">
    <inertial>
      <origin xyz="0.0 -0.0 0.0" rpy="0 0 0" />
      <mass value="0.000204873572147578" />
      <inertia ixx="1.09600066619755e-09" iyy="1.09600066619755e-09" izz="1.09600066619755e-09" ixy="-0.0" ixz="0.0" iyz="-0.0"/>
    </inertial>
    <visual>
      <origin xyz="0 0 0" rpy="0 0 0" />
      <geometry>
        <sphere radius="0.026" />
      </geometry>
      <material name="">
        <color rgba="1 1 0.4 1" />
      </material>
    </visual>
    <collision>
      <origin xyz="0 0 0" rpy="0 0 0"/>
      <geometry>
        <sphere radius="0.026" />
      </geometry>
    </collision>
    <!-- template_collision_placeholder -->
  </link>

  <joint name="RR_foot_joint" type="fixed">
    <origin xyz="0.0 -0.0 -0.26" rpy="-0.0 0.0 -0.0" />
    <parent link="RR_calf" />
    <child link="RR_foot" />
    <axis xyz="0 1 0" />
    <limit lower="0" upper="0" effort="0" velocity="0" />
  </joint>

  <!-- urdf auto generate tool -->
</robot>
